Workbook

Sheet Fact_Carrier_Weekly
A1: Year | B1: Week | C1: Start_Date | D1: End_Date | E1: CarrierID | F1: Carrier | G1: Carrier_Category | H1: Departures_Current | I1: Departures_Previous | J1: Passengers_Current | K1: PPB
A2: 2020 | B2: =_xlfn.ISOWEEKNUM(C2) -> 49 | C2: 44165 | D2: 44171 | E2: =VLOOKUP(F2,CarrierID!A:B,2,0) -> 1 | F2: Academy | G2: =VLOOKUP(F2,Carrier_Category!A:B,2,0) -> Commuter | H2: 37 | I2: 0 | J2: 615 | K2: =J2/H2 -> 16.621622
A3: 2020 | B3: =_xlfn.ISOWEEKNUM(C3) -> 49 | C3: 44165 | D3: 44171 | E3: =VLOOKUP(F3,CarrierID!A:B,2,0) -> 5 | F3: Greyhound | G3: =VLOOKUP(F3,Carrier_Category!A:B,2,0) -> Intercity | H3: 36 | I3: 0 | J3: 750 | K3: =J3/H3 -> 20.833333
A4: 2020 | B4: =_xlfn.ISOWEEKNUM(C4) -> 49 | C4: 44165 | D4: 44171 | E4: =VLOOKUP(F4,CarrierID!A:B,2,0) -> 8 | F4: Martz | G4: =VLOOKUP(F4,Carrier_Category!A:B,2,0) -> Commuter | H4: 17 | I4: 0 | J4: 486 | K4: =J4/H4 -> 28.588235
A5: 2020 | B5: =_xlfn.ISOWEEKNUM(C5) -> 49 | C5: 44165 | D5: 44171 | E5: =VLOOKUP(F5,CarrierID!A:B,2,0) -> 9 | F5: NJ Transit | G5: =VLOOKUP(F5,Carrier_Category!A:B,2,0) -> NJT | H5: 2108 | I5: 0 | J5: 26512 | K5: =J5/H5 -> 12.57685
A6: 2020 | B6: =_xlfn.ISOWEEKNUM(C6) -> 49 | C6: 44165 | D6: 44171 | E6: =VLOOKUP(F6,CarrierID!A:B,2,0) -> 7 | F6: Lakeland | G6: =VLOOKUP(F6,Carrier_Category!A:B,2,0) -> Commuter | H6: 13 | I6: 0 | J6: 274 | K6: =J6/H6 -> 21.076923
A7: 2020 | B7: =_xlfn.ISOWEEKNUM(C7) -> 49 | C7: 44165 | D7: 44171 | E7: =VLOOKUP(F7,CarrierID!A:B,2,0) -> 11 | F7: Trailways | G7: =VLOOKUP(F7,Carrier_Category!A:B,2,0) -> Intercity | H7: 11 | I7: 0 | J7: 212 | K7: =J7/H7 -> 19.272727
A8: 2020 | B8: =_xlfn.ISOWEEKNUM(C8) -> 49 | C8: 44165 | D8: 44171 | E8: =VLOOKUP(F8,CarrierID!A:B,2,0) -> 3 | F8: Coach USA | G8: =VLOOKUP(F8,Carrier_Category!A:B,2,0) -> Commuter | H8: 83 | I8: 0 | J8: 1626 | K8: =J8/H8 -> 19.590361
A9: 2020 | B9: =_xlfn.ISOWEEKNUM(C9) -> 49 | C9: 44165 | D9: 44171 | E9: =VLOOKUP(F9,CarrierID!A:B,2,0) -> 12 | F9: Trans-Bridge | G9: =VLOOKUP(F9,Carrier_Category!A:B,2,0) -> Commuter | H9: 12 | I9: 0 | J9: 319 | K9: =J9/H9 -> 26.583333
A10: 2020 | B10: =_xlfn.ISOWEEKNUM(C10) -> 49 | C10: 44165 | D10: 44171 | E10: =VLOOKUP(F10,CarrierID!A:B,2,0) -> 10 | F10: Peter Pan/Bonanza | G10: =VLOOKUP(F10,Carrier_Category!A:B,2,0) -> Intercity | H10: 14 | I10: 0 | J10: 301 | K10: =J10/H10 -> 21.5
A11: 2020 | B11: =_xlfn.ISOWEEKNUM(C11) -> 49 | C11: 44165 | D11: 44171 | E11: =VLOOKUP(F11,CarrierID!A:B,2,0) -> 2 | F11: Other | G11: =VLOOKUP(F11,Carrier_Category!A:B,2,0) -> Other | H11: 1 | I11: 0 | J11: 7 | K11: =J11/H11 -> 7
A12: 2020 | B12: =_xlfn.ISOWEEKNUM(C12) -> 49 | C12: 44165 | D12: 44171 | E12: =VLOOKUP(F12,CarrierID!A:B,2,0) -> 6 | F12: HCEE - Community | G12: =VLOOKUP(F12,Carrier_Category!A:B,2,0) -> Commuter | H12: 74 | I12: 0 | J12: 1199 | K12: =J12/H12 -> 16.202703
A13: 2020 | B13: =_xlfn.ISOWEEKNUM(C13) -> 50 | C13: 44172 | D13: 44176 | E13: =VLOOKUP(F13,CarrierID!A:B,2,0) -> 1 | F13: Academy | G13: =VLOOKUP(F13,Carrier_Category!A:B,2,0) -> Commuter | H13: 37 | I13: =H2 -> 37 | J13: 613 | K13: =J13/H13 -> 16.567568
A14: 2020 | B14: =_xlfn.ISOWEEKNUM(C14) -> 50 | C14: 44172 | D14: 44176 | E14: =VLOOKUP(F14,CarrierID!A:B,2,0) -> 5 | F14: Greyhound | G14: =VLOOKUP(F14,Carrier_Category!A:B,2,0) -> Intercity | H14: 33 | I14: =H3 -> 36 | J14: 702 | K14: =J14/H14 -> 21.272727
A15: 2020 | B15: =_xlfn.ISOWEEKNUM(C15) -> 50 | C15: 44172 | D15: 44176 | E15: =VLOOKUP(F15,CarrierID!A:B,2,0) -> 8 | F15: Martz | G15: =VLOOKUP(F15,Carrier_Category!A:B,2,0) -> Commuter | H15: 14 | I15: =H4 -> 17 | J15: 475 | K15: =J15/H15 -> 33.928571
A16: 2020 | B16: =_xlfn.ISOWEEKNUM(C16) -> 50 | C16: 44172 | D16: 44176 | E16: =VLOOKUP(F16,CarrierID!A:B,2,0) -> 9 | F16: NJ Transit | G16: =VLOOKUP(F16,Carrier_Category!A:B,2,0) -> NJT | H16: 2199 | I16: =H5 -> 2108 | J16: 27174 | K16: =J16/H16 -> 12.357435
A17: 2020 | B17: =_xlfn.ISOWEEKNUM(C17) -> 50 | C17: 44172 | D17: 44176 | E17: =VLOOKUP(F17,CarrierID!A:B,2,0) -> 7 | F17: Lakeland | G17: =VLOOKUP(F17,Carrier_Category!A:B,2,0) -> Commuter | H17: 13 | I17: =H6 -> 13 | J17: 280 | K17: =J17/H17 -> 21.538462
A18: 2020 | B18: =_xlfn.ISOWEEKNUM(C18) -> 50 | C18: 44172 | D18: 44176 | E18: =VLOOKUP(F18,CarrierID!A:B,2,0) -> 11 | F18: Trailways | G18: =VLOOKUP(F18,Carrier_Category!A:B,2,0) -> Intercity | H18: 11 | I18: =H7 -> 11 | J18: 188 | K18: =J18/H18 -> 17.090909
A19: 2020 | B19: =_xlfn.ISOWEEKNUM(C19) -> 50 | C19: 44172 | D19: 44176 | E19: =VLOOKUP(F19,CarrierID!A:B,2,0) -> 3 | F19: Coach USA | G19: =VLOOKUP(F19,Carrier_Category!A:B,2,0) -> Commuter | H19: 83 | I19: =H8 -> 83 | J19: 1605 | K19: =J19/H19 -> 19.337349
A20: 2020 | B20: =_xlfn.ISOWEEKNUM(C20) -> 50 | C20: 44172 | D20: 44176 | E20: =VLOOKUP(F20,CarrierID!A:B,2,0) -> 12 | F20: Trans-Bridge | G20: =VLOOKUP(F20,Carrier_Category!A:B,2,0) -> Commuter | H20: 12 | I20: =H9 -> 12 | J20: 310 | K20: =J20/H20 -> 25.833333
A21: 2020 | B21: =_xlfn.ISOWEEKNUM(C21) -> 50 | C21: 44172 | D21: 44176 | E21: =VLOOKUP(F21,CarrierID!A:B,2,0) -> 10 | F21: Peter Pan/Bonanza | G21: =VLOOKUP(F21,Carrier_Category!A:B,2,0) -> Intercity | H21: 12 | I21: =H10 -> 14 | J21: 251 | K21: =J21/H21 -> 20.916667
A22: 2020 | B22: =_xlfn.ISOWEEKNUM(C22) -> 50 | C22: 44172 | D22: 44176 | E22: =VLOOKUP(F22,CarrierID!A:B,2,0) -> 2 | F22: Other | G22: =VLOOKUP(F22,Carrier_Category!A:B,2,0) -> Other | H22: 1 | I22: =H11 -> 1 | J22: 8 | K22: =J22/H22 -> 8
A23: 2020 | B23: =_xlfn.ISOWEEKNUM(C23) -> 50 | C23: 44172 | D23: 44176 | E23: =VLOOKUP(F23,CarrierID!A:B,2,0) -> 6 | F23: HCEE - Community | G23: =VLOOKUP(F23,Carrier_Category!A:B,2,0) -> Commuter | H23: 74 | I23: =H12 -> 74 | J23: 1199 | K23: =J23/H23 -> 16.202703
A24: 2020 | B24: =_xlfn.ISOWEEKNUM(C24) -> 51 | C24: 44179 | D24: 44183 | E24: =VLOOKUP(F24,CarrierID!A:B,2,0) -> 1 | F24: Academy | G24: =VLOOKUP(F24,Carrier_Category!A:B,2,0) -> Commuter | H24: 37 | I24: =H13 -> 37 | J24: 581 | K24: =J24/H24 -> 15.702703
... A45: 2020 | B45: =_xlfn.ISOWEEKNUM(C45) -> 52 | C45: 44186 | D45: 44190 | E45: =VLOOKUP(F45,CarrierID!A:B,2,0) -> 6 | F45: HCEE - Community | G45: =VLOOKUP(F45,Carrier_Category!A:B,2,0) -> Commuter | H45: 69 | I45: =H34 -> 75 | J45: 1172 | K45: =J45/H45 -> 16.985507
A46: 2020 | B46: =_xlfn.ISOWEEKNUM(C46) -> 53 | C46: 44193 | D46: 44196 | E46: =VLOOKUP(F46,CarrierID!A:B,2,0) -> 1 | F46: Academy | G46: =VLOOKUP(F46,Carrier_Category!A:B,2,0) -> Commuter | I46: =H35 -> 31 | K46: =J46/H46 -> #DIV/0!
A47: 2020 | B47: =_xlfn.ISOWEEKNUM(C47) -> 53 | C47: 44193 | D47: 44196 | E47: =VLOOKUP(F47,CarrierID!A:B,2,0) -> 5 | F47: Greyhound | G47: =VLOOKUP(F47,Carrier_Category!A:B,2,0) -> Intercity | H47: 36 | I47: =H36 -> 40 | J47: 977 | K47: =J47/H47 -> 27.138889
A48: 2020 | B48: =_xlfn.ISOWEEKNUM(C48) -> 53 | C48: 44193 | D48: 44196 | E48: =VLOOKUP(F48,CarrierID!A:B,2,0) -> 8 | F48: Martz | G48: =VLOOKUP(F48,Carrier_Category!A:B,2,0) -> Commuter | H48: 13 | I48: =H37 -> 13 | J48: 429 | K48: =J48/H48 -> 33
A49: 2020 | B49: =_xlfn.ISOWEEKNUM(C49) -> 53 | C49: 44193 | D49: 44196 | E49: =VLOOKUP(F49,CarrierID!A:B,2,0) -> 9 | F49: NJ Transit | G49: =VLOOKUP(F49,Carrier_Category!A:B,2,0) -> NJT | H49: 2001 | I49: =H38 -> 2125 | J49: 22446 | K49: =J49/H49 -> 11.217391
A50: 2020 | B50: =_xlfn.ISOWEEKNUM(C50) -> 53 | C50: 44193 | D50: 44196 | E50: =VLOOKUP(F50,CarrierID!A:B,2,0) -> 7 | F50: Lakeland | G50: =VLOOKUP(F50,Carrier_Category!A:B,2,0) -> Commuter | H50: 12 | I50: =H39 -> 13 | J50: 224 | K50: =J50/H50 -> 18.666667
A51: 2020 | B51: =_xlfn.ISOWEEKNUM(C51) -> 53 | C51: 44193 | D51: 44196 | E51: =VLOOKUP(F51,CarrierID!A:B,2,0) -> 11 | F51: Trailways | G51: =VLOOKUP(F51,Carrier_Category!A:B,2,0) -> Intercity | H51: 11 | I51: =H40 -> 11 | J51: 227 | K51: =J51/H51 -> 20.636364
A52: 2020 | B52: =_xlfn.ISOWEEKNUM(C52) -> 53 | C52: 44193 | D52: 44196 | E52: =VLOOKUP(F52,CarrierID!A:B,2,0) -> 3 | F52: Coach USA | G52: =VLOOKUP(F52,Carrier_Category!A:B,2,0) -> Commuter | H52: 80 | I52: =H41 -> 83 | J52: 1316 | K52: =J52/H52 -> 16.45
A53: 2020 | B53: =_xlfn.ISOWEEKNUM(C53) -> 53 | C53: 44193 | D53: 44196 | E53: =VLOOKUP(F53,CarrierID!A:B,2,0) -> 12 | F53: Trans-Bridge | G53: =VLOOKUP(F53,Carrier_Category!A:B,2,0) -> Commuter | H53: 12 | I53: =H42 -> 12 | J53: 224 | K53: =J53/H53 -> 18.666667
A54: 2020 | B54: =_xlfn.ISOWEEKNUM(C54) -> 53 | C54: 44193 | D54: 44196 | E54: =VLOOKUP(F54,CarrierID!A:B,2,0) -> 10 | F54: Peter Pan/Bonanza | G54: =VLOOKUP(F54,Carrier_Category!A:B,2,0) -> Intercity | H54: 10 | I54: =H43 -> 9 | J54: 275 | K54: =J54/H54 -> 27.5
A55: 2020 | B55: =_xlfn.ISOWEEKNUM(C55) -> 53 | C55: 44193 | D55: 44196 | E55: =VLOOKUP(F55,CarrierID!A:B,2,0) -> 2 | F55: Other | G55: =VLOOKUP(F55,Carrier_Category!A:B,2,0) -> Other | H55: 1 | I55: =H44 -> 1 | J55: 6 | K55: =J55/H55 -> 6
A56: 2020 | B56: =_xlfn.ISOWEEKNUM(C56) -> 53 | C56: 44193 | D56: 44196 | E56: =VLOOKUP(F56,CarrierID!A:B,2,0) -> 6 | F56: HCEE - Community | G56: =VLOOKUP(F56,Carrier_Category!A:B,2,0) -> Commuter | I56: =H45 -> 69 | K56: =J56/H56 -> #DIV/0!
A57: 2021 | B57: =_xlfn.ISOWEEKNUM(C57) -> 1 | C57: 44200 | D57: 44204 | E57: =VLOOKUP(F57,CarrierID!A:B,2,0) -> 1 | F57: Academy | G57: =VLOOKUP(F57,Carrier_Category!A:B,2,0) -> Commuter | H57: 37 | I57: =H46 -> 0 | J57: 590 | K57: =J57/H57 -> 15.945946
A58: 2021 | B58: =_xlfn.ISOWEEKNUM(C58) -> 1 | C58: 44200 | D58: 44204 | E58: =VLOOKUP(F58,CarrierID!A:B,2,0) -> 5 | F58: Greyhound | G58: =VLOOKUP(F58,Carrier_Category!A:B,2,0) -> Intercity | H58: 34 | I58: =H47 -> 36 | J58: 900 | K58: =J58/H58 -> 26.470588
A59: 2021 | B59: =_xlfn.ISOWEEKNUM(C59) -> 1 | C59: 44200 | D59: 44204 | E59: =VLOOKUP(F59,CarrierID!A:B,2,0) -> 8 | F59: Martz | G59: =VLOOKUP(F59,Carrier_Category!A:B,2,0) -> Commuter | H59: 13 | I59: =H48 -> 13 | J59: 456 | K59: =J59/H59 -> 35.076923
A60: 2021 | B60: =_xlfn.ISOWEEKNUM(C60) -> 1 | C60: 44200 | D60: 44204 | E60: =VLOOKUP(F60,CarrierID!A:B,2,0) -> 9 | F60: NJ Transit | G60: =VLOOKUP(F60,Carrier_Category!A:B,2,0) -> NJT | H60: 2146 | I60: =H49 -> 2001 | J60: 25865 | K60: =J60/H60 -> 12.052656
...

Sheet Reference_2019
A1: Carrier | B1: Departures_2019 | C1: Passengers_2019 | D1: Description
A2: Academy | B2: 113 | C2: 4152 | D2: Fall 2019 Typical Weekday
A3: Greyhound | B3: 118 | C3: 3262 | D3: Fall 2019 Typical Weekday
A4: Martz | B4: 47 | C4: 1771 | D4: Fall 2019 Typical Weekday
A5: NJ Transit | B5: 2500 | C5: 86541 | D5: Fall 2019 Typical Weekday
A6: Lakeland | B6: 75 | C6: 2819 | D6: Fall 2019 Typical Weekday
A7: Trailways | B7: 35 | C7: 752 | D7: Fall 2019 Typical Weekday
A8: Coach USA | B8: 460 | C8: 14129 | D8: Fall 2019 Typical Weekday
A9: TransBridge | B9: 61 | C9: 1843 | D9: Fall 2019 Typical Weekday
A10: Peter Pan/Bonanza | B10: 44 | C10: 1048 | D10: Fall 2019 Typical Weekday
A11: Other | B11: 3 | C11: 55 | D11: Fall 2019 Typical Weekday
A12: HCEE - Community | B12: 295 | C12: 5504 | D12: Fall 2019 Typical Weekday
A13: Total | B13: =SUM(B2:B12) -> 3751 | C13: =SUM(C2:C12) -> 121876

Sheet Totals_Terminal
A1: Year | B1: Start _Date | C1: End _Date | D1: TotalDepartures | E1: TotalPassengers
A2: =YEAR(B2) -> 2020 | B2: 44165 | C2: =VLOOKUP(B2,Fact_Carrier_Weekly!C:D,2,0) -> 44171 | D2: =SUMIF(Fact_Carrier_Weekly!$C:$C, $B2, Fact_Carrier_Weekly!$H:$H) -> 2406 | E2: =SUMIF(Fact_Carrier_Weekly!$C:$C, $B2, Fact_Carrier_Weekly!$J:$J) -> 32301 | H2: Start Date | I2: (All)
A3: =YEAR(B3) -> 2020 | B3: 44172 | C3: =VLOOKUP(B3,Fact_Carrier_Weekly!C:D,2,0) -> 44176 | D3: =SUMIF(Fact_Carrier_Weekly!$C:$C, $B3, Fact_Carrier_Weekly!$H:$H) -> 2489 | E3: =SUMIF(Fact_Carrier_Weekly!$C:$C, $B3, Fact_Carrier_Weekly!$J:$J) -> 32805 | H3: End Date | I3: (All)
A4: =YEAR(B4) -> 2020 | B4: 44179 | C4: =VLOOKUP(B4,Fact_Carrier_Weekly!C:D,2,0) -> 44183 | D4: =SUMIF(Fact_Carrier_Weekly!$C:$C, $B4, Fact_Carrier_Weekly!$H:$H) -> 2326 | E4: =SUMIF(Fact_Carrier_Weekly!$C:$C, $B4, Fact_Carrier_Weekly!$J:$J) -> 32046
A5: =YEAR(B5) -> 2020 | B5: 44186 | C5: =VLOOKUP(B5,Fact_Carrier_Weekly!C:D,2,0) -> 44190 | D5: =SUMIF(Fact_Carrier_Weekly!$C:$C, $B5, Fact_Carrier_Weekly!$H:$H) -> 2407 | E5: =SUMIF(Fact_Carrier_Weekly!$C:$C, $B5, Fact_Carrier_Weekly!$J:$J) -> 30884 | H5: Row Labels | I5: Sum of TotalDepartures | J5: Sum of TotalPassengers
A6: =YEAR(B6) -> 2020 | B6: 44193 | C6: =VLOOKUP(B6,Fact_Carrier_Weekly!C:D,2,0) -> 44196 | D6: =SUMIF(Fact_Carrier_Weekly!$C:$C, $B6, Fact_Carrier_Weekly!$H:$H) -> 2176 | E6: =SUMIF(Fact_Carrier_Weekly!$C:$C, $B6, Fact_Carrier_Weekly!$J:$J) -> 26124 | H6: 2020 | I6: 11804 | J6: 154160
A7: =YEAR(B7) -> 2021 | B7: 44200 | C7: =VLOOKUP(B7,Fact_Carrier_Weekly!C:D,2,0) -> 44204 | D7: =SUMIF(Fact_Carrier_Weekly!$C:$C, $B7, Fact_Carrier_Weekly!$H:$H) -> 2431 | E7: =SUMIF(Fact_Carrier_Weekly!$C:$C, $B7, Fact_Carrier_Weekly!$J:$J) -> 31629 | H7: 2021 | I7: 125114.4 | J7: 2298091
A8: =YEAR(B8) -> 2021 | B8: 44207 | C8: =VLOOKUP(B8,Fact_Carrier_Weekly!C:D,2,0) -> 44211 | D8: =SUMIF(Fact_Carrier_Weekly!$C:$C, $B8, Fact_Carrier_Weekly!$H:$H) -> 2373 | E8: =SUMIF(Fact_Carrier_Weekly!$C:$C, $B8, Fact_Carrier_Weekly!$J:$J) -> 31777 | H8: 2022 | I8: 133642 | J8: 3562422.2
A9: =YEAR(B9) -> 2021 | B9: 44214 | C9: =VLOOKUP(B9,Fact_Carrier_Weekly!C:D,2,0) -> 44218 | D9: =SUMIF(Fact_Carrier_Weekly!$C:$C, $B9, Fact_Carrier_Weekly!$H:$H) -> 2319 | E9: =SUMIF(Fact_Carrier_Weekly!$C:$C, $B9, Fact_Carrier_Weekly!$J:$J) -> 29413 | H9: 2023 | I9: 145317 | J9: 4520408.4
A10: =YEAR(B10) -> 2021 | B10: 44221 | C10: =VLOOKUP(B10,Fact_Carrier_Weekly!C:D,2,0) -> 44225 | D10: =SUMIF(Fact_Carrier_Weekly!$C:$C, $B10, Fact_Carrier_Weekly!$H:$H) -> 2336 | E10: =SUMIF(Fact_Carrier_Weekly!$C:$C, $B10, Fact_Carrier_Weekly!$J:$J) -> 32199 | H10: 2024 | I10: 143135 | J10: 4707851
A11: =YEAR(B11) -> 2021 | B11: 44228 | C11: =VLOOKUP(B11,Fact_Carrier_Weekly!C:D,2,0) -> 44232 | D11: =SUMIF(Fact_Carrier_Weekly!$C:$C, $B11, Fact_Carrier_Weekly!$H:$H) -> 2358 | E11: =SUMIF(Fact_Carrier_Weekly!$C:$C, $B11, Fact_Carrier_Weekly!$J:$J) -> 30725 | H11: 2025 | I11: 88826 | J11: 2979836
A12: =YEAR(B12) -> 2021 | B12: 44235 | C12: =VLOOKUP(B12,Fact_Carrier_Weekly!C:D,2,0) -> 44239 | D12: =SUMIF(Fact_Carrier_Weekly!$C:$C, $B12, Fact_Carrier_Weekly!$H:$H) -> 2328 | E12: =SUMIF(Fact_Carrier_Weekly!$C:$C, $B12, Fact_Carrier_Weekly!$J:$J) -> 32185 | H12: Grand Total | I12: 647838.4 | J12: 18222769
A13: =YEAR(B13) -> 2021 | B13: 44242 | C13: =VLOOKUP(B13,Fact_Carrier_Weekly!C:D,2,0) -> 44246 | D13: =SUMIF(Fact_Carrier_Weekly!$C:$C, $B13, Fact_Carrier_Weekly!$H:$H) -> 2559 | E13: =SUMIF(Fact_Carrier_Weekly!$C:$C, $B13, Fact_Carrier_Weekly!$J:$J) -> 32827
A14: =YEAR(B14) -> 2021 | B14: 44249 | C14: =VLOOKUP(B14,Fact_Carrier_Weekly!C:D,2,0) -> 44253 | D14: =SUMIF(Fact_Carrier_Weekly!$C:$C, $B14, Fact_Carrier_Weekly!$H:$H) -> 2359 | E14: =SUMIF(Fact_Carrier_Weekly!$C:$C, $B14, Fact_Carrier_Weekly!$J:$J) -> 32990
A15: =YEAR(B15) -> 2021 | B15: 44257 | C15: =VLOOKUP(B15,Fact_Carrier_Weekly!C:D,2,0) -> 44260 | D15: =SUMIF(Fact_Carrier_Weekly!$C:$C, $B15, Fact_Carrier_Weekly!$H:$H) -> 2372 | E15: =SUMIF(Fact_Carrier_Weekly!$C:$C, $B15, Fact_Carrier_Weekly!$J:$J) -> 35070
A16: =YEAR(B16) -> 2021 | B16: 44263 | C16: =VLOOKUP(B16,Fact_Carrier_Weekly!C:D,2,0) -> 44267 | D16: =SUMIF(Fact_Carrier_Weekly!$C:$C, $B16, Fact_Carrier_Weekly!$H:$H) -> 2384 | E16: =SUMIF(Fact_Carrier_Weekly!$C:$C, $B16, Fact_Carrier_Weekly!$J:$J) -> 34906
A17: =YEAR(B17) -> 2021 | B17: 44270 | C17: =VLOOKUP(B17,Fact_Carrier_Weekly!C:D,2,0) -> 44274 | D17: =SUMIF(Fact_Carrier_Weekly!$C:$C, $B17, Fact_Carrier_Weekly!$H:$H) -> 2426 | E17: =SUMIF(Fact_Carrier_Weekly!$C:$C, $B17, Fact_Carrier_Weekly!$J:$J) -> 34201
A18: =YEAR(B18) -> 2021 | B18: 44277 | C18: =VLOOKUP(B18,Fact_Carrier_Weekly!C:D,2,0) -> 44281 | D18: =SUMIF(Fact_Carrier_Weekly!$C:$C, $B18, Fact_Carrier_Weekly!$H:$H) -> 2339 | E18: =SUMIF(Fact_Carrier_Weekly!$C:$C, $B18, Fact_Carrier_Weekly!$J:$J) -> 33989
A19: =YEAR(B19) -> 2021 | B19: 44284 | C19: =VLOOKUP(B19,Fact_Carrier_Weekly!C:D,2,0) -> 44288 | D19: =SUMIF(Fact_Carrier_Weekly!$C:$C, $B19, Fact_Carrier_Weekly!$H:$H) -> 2439 | E19: =SUMIF(Fact_Carrier_Weekly!$C:$C, $B19, Fact_Carrier_Weekly!$J:$J) -> 35640
A20: =YEAR(B20) -> 2021 | B20: 44291 | C20: =VLOOKUP(B20,Fact_Carrier_Weekly!C:D,2,0) -> 44295 | D20: =SUMIF(Fact_Carrier_Weekly!$C:$C, $B20, Fact_Carrier_Weekly!$H:$H) -> 2549 | E20: =SUMIF(Fact_Carrier_Weekly!$C:$C, $B20, Fact_Carrier_Weekly!$J:$J) -> 37202
A21: =YEAR(B21) -> 2021 | B21: 44298 | C21: =VLOOKUP(B21,Fact_Carrier_Weekly!C:D,2,0) -> 44302 | D21: =SUMIF(Fact_Carrier_Weekly!$C:$C, $B21, Fact_Carrier_Weekly!$H:$H) -> 2563 | E21: =SUMIF(Fact_Carrier_Weekly!$C:$C, $B21, Fact_Carrier_Weekly!$J:$J) -> 36468
A22: =YEAR(B22) -> 2021 | B22: 44305 | C22: =VLOOKUP(B22,Fact_Carrier_Weekly!C:D,2,0) -> 44309 | D22: =SUMIF(Fact_Carrier_Weekly!$C:$C, $B22, Fact_Carrier_Weekly!$H:$H) -> 2448 | E22: =SUMIF(Fact_Carrier_Weekly!$C:$C, $B22, Fact_Carrier_Weekly!$J:$J) -> 38491
A23: =YEAR(B23) -> 2021 | B23: 44312 | C23: =VLOOKUP(B23,Fact_Carrier_Weekly!C:D,2,0) -> 44316 | D23: =SUMIF(Fact_Carrier_Weekly!$C:$C, $B23, Fact_Carrier_Weekly!$H:$H) -> 2583 | E23: =SUMIF(Fact_Carrier_Weekly!$C:$C, $B23, Fact_Carrier_Weekly!$J:$J) -> 39306
A24: =YEAR(B24) -> 2021 | B24: 44319 | C24: =VLOOKUP(B24,Fact_Carrier_Weekly!C:D,2,0) -> 44323 | D24: =SUMIF(Fact_Carrier_Weekly!$C:$C, $B24, Fact_Carrier_Weekly!$H:$H) -> 2558 | E24: =SUMIF(Fact_Carrier_Weekly!$C:$C, $B24, Fact_Carrier_Weekly!$J:$J) -> 38612
... A240: =YEAR(B240) -> 2025 | B240: 45866 | C240: =VLOOKUP(B240,Fact_Carrier_Weekly!C:D,2,0) -> 45870 | D240: =SUMIF(Fact_Carrier_Weekly!$C:$C, $B240, Fact_Carrier_Weekly!$H:$H) -> 3035 | E240: =SUMIF(Fact_Carrier_Weekly!$C:$C, $B240, Fact_Carrier_Weekly!$J:$J) -> 101824

Sheet CarrierID
A1: CarrierName | B1: CarrierID
A2: Academy | B2: 1
A3: Other | B3: 2
A4: Coach USA | B4: 3
A5: DeCamp | B5: 4
A6: Greyhound | B6: 5
A7: HCEE - Community | B7: 6
A8: Lakeland | B8: 7
A9: Martz | B9: 8
A10: NJ Transit | B10: 9
A11: Peter Pan/Bonanza | B11: 10
A12: Trailways | B12: 11
A13: Trans-Bridge | B13: 12

Sheet Carrier_Category
A1: Carrier | B1: Carrier_Category
A2: Academy | B2: Commuter
A3: Other | B3: Other
A4: Coach USA | B4: Commuter
A5: DeCamp | B5: Commuter
A6: Greyhound | B6: Intercity
A7: HCEE - Community | B7: Commuter
A8: Lakeland | B8: Commuter
A9: Martz | B9: Commuter
A10: NJ Transit | B10: NJT
A11: Peter Pan/Bonanza | B11: Intercity
A12: Trailways | B12: Intercity
A13: Trans-Bridge | B13: Commuter
